Workbook
Name CategoryList: 'Client Setup'!$A$23:$A$33
Name CategoryTable: 'Client Setup'!$A$23:$B$33
Name DestinationList: 'Client Setup'!$I$61:$I$71
Name DriveRoutes: 'Client Setup'!$A$57:$B$65
Name FlightTypes: 'Client Setup'!$A$75:$C$77
Name HotelRates: 'Client Setup'!$A$82:$C$90
Name LocationList: 'Client Setup'!$A$124:$A$145
Name OriginList: 'Client Setup'!$I$53:$I$58
Name PerDiemRates: 'Client Setup'!$A$94:$C$95
Name TrainRoutes: 'Client Setup'!$A$69:$C$71
Name VehicleRates: 'Client Setup'!$A$105:$G$114

Sheet Client Setup
A2: Client Setup — Complete Once Per Program | H2: Color | I2: Meaning
I3: Dropdown — click to select
A4: EVENT DETAILS | I4: Manual entry or formula
A5: Client Name: | B5: Alex Stack
A6: Event Date: | B6: 46396
A7: Guest Count: | B7: 60
A8: Service Style: | B8: Family Style
A9: Alcohol: | B9: Full Bar
A10: Event Time: | B10: 6-9
A11: Company Name: | B11: QCED
A12: Program Name: | B12: Sample Program
A13: Client Hotel:
A15: LOCATION & TAX RATES
A16: State / Location: | B16: Wilson NC | D16: Tax rates auto-populate from location
A17: Food Tax Rate: | B17: =IF(B16="","",VLOOKUP(B16,$A$124:$D$145,2,FALSE)) | D17: Tax on food & NA beverages
A18: Alcohol Tax Rate: | B18: =IF(B16="","",VLOOKUP(B16,$A$124:$D$145,3,FALSE)) | D18: Tax on bar/alcohol
A19: General Sales Tax Rate: | B19: =IF(B16="","",VLOOKUP(B16,$A$124:$D$145,4,FALSE)) | D19: Tax on equipment, rentals, staffing
A21: PRICING & COMMISSION
A22: Category | B22: Markup % | C22: Note
A23: Catering & F&B | B23: 0.54 | C23: Floor — clients compare per-head pricing
A24: Venues & Room Rentals | B24: 0.6 | C24: Full venue relationship management
A25: AV & Production | B25: 0.65 | C25: Technical coordination, hard to price-shop
A26: Décor & Design | B26: 0.85 | C26: Custom creative — no comparison exists
A27: Entertainment | B27: 0.75 | C27: Talent sourcing, contracts, riders
A28: Activities & Experiences | B28: 0.75 | C28: Curation, coordination, permitting
A29: Transportation | B29: 0.75 | C29: Route planning, high-liability
A30: Staffing & Labor | B30: 0.9 | C30: Recruitment, scheduling, management
A31: Purchased / Sourced Items | B31: 2 | C31: Small items, disproportionate time (3×)
A32: Delivery & Logistics | B32: 0.85 | C32: Timing risk, damage liability
A33: Tours & Guided Experiences | B33: 0.65 | C33: Guide sourcing, route design
A34: Absolute Floor: 54% | C34: No exceptions without owner approval
A35: CC Processing Fee %: | C35: 0.035 | D35: Applied to subtotal
A36: Third-Party Commission: | C36: 0.05 | D36: Select commission rate
A37: Global DMC (6.5%): | C37: Yes | D37: Yes = 6.5% applied
A39: RESTAURANT FEE DEFAULTS (can be overridden per venue)
A40: Service Charge: | C40: 20% | D40: 20%, 21.5%, or None
A41: Gratuity: | C41: 20% | D41: 20% or None
A42: Admin Fee: | C42: 5% | D42: 5% or None
A44: HOW TO USE
A45: 1. Fill out all fields above — this information feeds into every estimate tab.
...

Sheet Venue Estimate
A2: Restaurant / Venue Estimate | H2: Color | I2: Meaning
I3: Dropdown — click to select
A4: VENUE DETAILS | I4: Manual entry or formula
A5: Venue / Restaurant Name: | I5: Copy & paste into Canva
A6: Room / Space:
A7: F&B Minimum: | I7: PRIVATE DINING ESTIMATE
A8: Is Venue Rental Taxable? | B8: Yes | I8: ='Client Setup'!B5 | K8: =B5
A9: Client: | B9: ='Client Setup'!B5 | I9: =TEXT('Client Setup'!B6,"MMMM D, YYYY") | K9: ='Client Setup'!B7&" Guests"
A10: Guest Count: | B10: ='Client Setup'!B7
A11: Location: | B11: ='Client Setup'!B16 | I11: Item | J11: Amount | K11: PP Price
A12: Company: | B12: ='Client Setup'!B11
A13: Program: | B13: ='Client Setup'!B12
A14: Client Hotel: | B14: ='Client Setup'!B13
A15: Event Time: | B15: ='Client Setup'!B10 | I15: Menu | J15: =ROUNDUP((E24+E26)/50,0)*50 | K15: =IF('Client Setup'!B7>0,CEILING(J12/'Client Setup'!B7,1),0)
A16: VENUE FEE OVERRIDES (defaults from Client Setup — change yellow fields to override) | I16: Bar Package | J16: =ROUNDUP(E25/50,0)*50 | K16: =IF('Client Setup'!B7>0,CEILING(J13/'Client Setup'!B7,1),0)
A17: Service Charge: | C17: ='Client Setup'!C40 | D17: 20%, 21.5%, or None | I17: Staffing | J17: =ROUNDUP((E28+SUM(E38:E40))/50,0)*50 | K17: =IF('Client Setup'!B7>0,CEILING(J14/'Client Setup'!B7,1),0)
A18: Gratuity: | C18: ='Client Setup'!C41 | D18: 20% or None | I18: Equipment | J18: =ROUNDUP((E29+E30+E31)/50,0)*50 | K18: =IF('Client Setup'!B7>0,CEILING(J15/'Client Setup'!B7,1),0)
A19: Admin Fee: | C19: ='Client Setup'!C42 | D19: 5% or None | I19: Venue Rental | J19: =ROUNDUP((E33+E34+E35)/50,0)*50 | K19: =IF('Client Setup'!B7>0,CEILING(J16/'Client Setup'!B7,1),0)
I20: Production Fee | J20: =ROUNDUP((E51+E52+E53+E55+E56)/100,0)*100 | K20: =IF('Client Setup'!B7>0,CEILING(J17/'Client Setup'!B7,1),0)
A21: COST BUILD | I21: Tax | J21: =ROUNDUP((E44+E45+E47+E50)/50,0)*50 | K21: =IF('Client Setup'!B7>0,CEILING(J18/'Client Setup'!B7,1),0)
A22: Line Item | B22: Qty | C22: Unit Price | D22: Our Cost | E22: Client Cost | F22: Tax Rate | G22: Category
A23: FOOD & BEVERAGE (F&B Tax Applied) | I23: TOTAL ESTIMATE | J23: =SUM(J12:J18) | K23: =IF('Client Setup'!B7>0,CEILING(J20/'Client Setup'!B7,1),0)
A24: Per Person Food | B24: ='Client Setup'!B7 | D24: =B24*C24 | E24: =IFERROR(D24*(1+VLOOKUP(G24,CategoryTable,2,FALSE)),0) | F24: ='Client Setup'!B17 | G24: Catering & F&B | I24: Guest Count | J24: ='Client Setup'!B7
A25: Bar Package | B25: ='Client Setup'!B7 | D25: =B25*C25 | E25: =IFERROR(D25*(1+VLOOKUP(G25,CategoryTable,2,FALSE)),0) | F25: ='Client Setup'!B18 | G25: Catering & F&B
A26: NA Beverages | B26: ='Client Setup'!B7 | D26: =B26*C26 | E26: =IFERROR(D26*(1+VLOOKUP(G26,CategoryTable,2,FALSE)),0) | F26: ='Client Setup'!B17 | G26: Catering & F&B
A27: TAXABLE EQUIPMENT, RENTALS & STAFFING (General Sales Tax) | I27: TEAM NOTES
A28: Staffing | B28: 1 | D28: =B28*C28 | E28: =IFERROR(D28*(1+VLOOKUP(G28,CategoryTable,2,FALSE)),0) | F28: ='Client Setup'!B19 | G28: Staffing & Labor | I28: Venue Contact:
A29: Catering Equipment | B29: 1 | D29: =B29*C29 | E29: =IFERROR(D29*(1+VLOOKUP(G29,CategoryTable,2,FALSE)),0) | F29: ='Client Setup'!B19 | G29: AV & Production
A30: Rental Equipment | B30: 1 | D30: =B30*C30 | E30: =IFERROR(D30*(1+VLOOKUP(G30,CategoryTable,2,FALSE)),0) | F30: ='Client Setup'!B19 | G30: Décor & Design | I30: Menu Notes:
A31: Additional Equipment | B31: 1 | D31: =B31*C31 | E31: =IFERROR(D31*(1+VLOOKUP(G31,CategoryTable,2,FALSE)),0) | F31: ='Client Setup'!B19 | G31: AV & Production
A32: VENUE FEES (Taxable if toggled above)
A33: Venue / Room Rental | B33: 1 | D33: =B33*C33 | E33: =IFERROR(D33*(1+VLOOKUP(G33,CategoryTable,2,FALSE)),0) | F33: =IF(B8="Yes",'Client Setup'!B19,0) | G33: Venues & Room Rentals | I33: Logistics:
A34: Additional Venue Space | B34: 1 | D34: =B34*C34 | E34: =IFERROR(D34*(1+VLOOKUP(G34,CategoryTable,2,FALSE)),0) | F34: =IF(B8="Yes",'Client Setup'!B19,0) | G34: Venues & Room Rentals
A35: Additional Services | B35: 1 | D35: =B35*C35 | E35: =IFERROR(D35*(1+VLOOKUP(G35,CategoryTable,2,FALSE)),0) | F35: =IF(B8="Yes",'Client Setup'!B19,0) | G35: Venues & Room Rentals | I35: Additional Notes:
A37: NON-TAXABLE QC STAFFING
A38: QC Event Staff | B38: =IF('Client Setup'!B7>100,3,IF('Client Setup'!B7>50,2,1)) | C38: 500 | D38: =B38*C38 | E38: =IFERROR(D38*(1+VLOOKUP(G38,CategoryTable,2,FALSE)),0) | F38: 0 | G38: Staffing & Labor
D39: =B39*C39 | E39: =IFERROR(D39*(1+VLOOKUP(G39,CategoryTable,2,FALSE)),0) | F39: 0 | G39: Staffing & Labor
D40: =B40*C40 | E40: =IFERROR(D40*(1+VLOOKUP(G40,CategoryTable,2,FALSE)),0) | F40: 0 | G40: Staffing & Labor
A42: ESTIMATE SUMMARY
A43: F&B Subtotal | D43: =SUM(D24:D26) | E43: =SUM(E24:E26)
...

Sheet Decor Estimate
A2: Decor & Production Estimate
A4: EVENT INFO (from Client Setup) | J4: DETAILED CLIENT VIEW | M4: SUMMARY VIEW
A5: Client: | B5: ='Client Setup'!B5 | J5: Itemized — each section is one Canva slide | M5: Category totals for client
A6: Event Date: | B6: ='Client Setup'!B6
A7: Guest Count: | B7: ='Client Setup'!B7 | J7: DECOR & PRODUCTION ESTIMATE | M7: DECOR & PRODUCTION ESTIMATE
A8: Location: | B8: ='Client Setup'!B16 | J8: Color | K8: Meaning | M8: ='Client Setup'!B5 | N8: ='Client Setup'!B7&" Guests"
A9: Venue: | E9: Event Time: | F9: ='Client Setup'!B10 | J9: =TEXT('Client Setup'!B6,"MMMM D, YYYY") | K9: Dropdown — click to select | M9: =TEXT('Client Setup'!B6,"MMMM D, YYYY")
A10: Company: | B10: ='Client Setup'!B11 | K10: Manual entry or formula
A11: Program: | B11: ='Client Setup'!B12
A12: Client Hotel: | B12: ='Client Setup'!B13
A13: FLORALS
A14: Item | B14: Vendor | C14: Qty | D14: Unit Price | E14: Our Cost | F14: Client Cost | G14: Tax Rate | H14: Notes / Description | I14: Category | J14: Item | K14: Amount | M14: Category | N14: Amount
A15: TAXABLE FLORAL PRODUCT | J15: =A13 | M15: =A13 | N15: =ROUNDUP(F30/50,0)*50
E16: =C16*D16 | F16: =IFERROR(E16*(1+VLOOKUP(I16,CategoryTable,2,FALSE)),0) | G16: ='Client Setup'!B19 | I16: Décor & Design | J16: =IF(A16="","",A16&" x"&C16) | K16: =IF(A16="","",ROUNDUP(F16/10,0)*10) | M16: Seating | N16: =ROUNDUP(SUM(F35:F42)/50,0)*50
E17: =C17*D17 | F17: =IFERROR(E17*(1+VLOOKUP(I17,CategoryTable,2,FALSE)),0) | G17: ='Client Setup'!B19 | I17: Décor & Design | J17: =IF(A17="","",A17&" x"&C17) | K17: =IF(A17="","",ROUNDUP(F17/10,0)*10) | M17: Lounge Furniture | N17: =ROUNDUP(SUM(F44:F51)/50,0)*50
E18: =C18*D18 | F18: =IFERROR(E18*(1+VLOOKUP(I18,CategoryTable,2,FALSE)),0) | G18: ='Client Setup'!B19 | I18: Décor & Design | J18: =IF(A18="","",A18&" x"&C18) | K18: =IF(A18="","",ROUNDUP(F18/10,0)*10) | M18: Tables | N18: =ROUNDUP(SUM(F53:F60)/50,0)*50
E19: =C19*D19 | F19: =IFERROR(E19*(1+VLOOKUP(I19,CategoryTable,2,FALSE)),0) | G19: ='Client Setup'!B19 | I19: Décor & Design | J19: =IF(A19="","",A19&" x"&C19) | K19: =IF(A19="","",ROUNDUP(F19/10,0)*10) | M19: Decor & Accessories | N19: =ROUNDUP(SUM(F62:F67)/50,0)*50
E20: =C20*D20 | F20: =IFERROR(E20*(1+VLOOKUP(I20,CategoryTable,2,FALSE)),0) | G20: ='Client Setup'!B19 | I20: Décor & Design | J20: =IF(A20="","",A20&" x"&C20) | K20: =IF(A20="","",ROUNDUP(F20/10,0)*10) | M20: Delivery & Fees | N20: =ROUNDUP((SUM(F27:F29)+SUM(F69:F74)+SUM(F91:F95))/50,0)*50
E21: =C21*D21 | F21: =IFERROR(E21*(1+VLOOKUP(I21,CategoryTable,2,FALSE)),0) | G21: ='Client Setup'!B19 | I21: Décor & Design | J21: =IF(A21="","",A21&" x"&C21) | K21: =IF(A21="","",ROUNDUP(F21/10,0)*10) | M21: =A77 | N21: =ROUNDUP(SUM(F80:F89)/50,0)*50
E22: =C22*D22 | F22: =IFERROR(E22*(1+VLOOKUP(I22,CategoryTable,2,FALSE)),0) | G22: ='Client Setup'!B19 | I22: Décor & Design | J22: =IF(A22="","",A22&" x"&C22) | K22: =IF(A22="","",ROUNDUP(F22/10,0)*10) | M22: Tax | N22: =ROUNDUP(F100/50,0)*50
E23: =C23*D23 | F23: =IFERROR(E23*(1+VLOOKUP(I23,CategoryTable,2,FALSE)),0) | G23: ='Client Setup'!B19 | I23: Décor & Design | J23: =IF(A23="","",A23&" x"&C23) | K23: =IF(A23="","",ROUNDUP(F23/10,0)*10)
E24: =C24*D24 | F24: =IFERROR(E24*(1+VLOOKUP(I24,CategoryTable,2,FALSE)),0) | G24: ='Client Setup'!B19 | I24: Décor & Design | J24: =IF(A24="","",A24&" x"&C24) | K24: =IF(A24="","",ROUNDUP(F24/10,0)*10) | M24: TOTAL ESTIMATE | N24: =SUM(N15:N22)
E25: =C25*D25 | F25: =IFERROR(E25*(1+VLOOKUP(I25,CategoryTable,2,FALSE)),0) | G25: ='Client Setup'!B19 | I25: Décor & Design | J25: =IF(A25="","",A25&" x"&C25) | K25: =IF(A25="","",ROUNDUP(F25/10,0)*10) | M25: Guest Count | N25: ='Client Setup'!B7
A26: NON-TAXABLE FLORAL FEES | J26: =IF(A27="","",A27) | K26: =IF(A27="","",ROUNDUP(F27/10,0)*10)
E27: =D27 | F27: =IFERROR(E27*(1+VLOOKUP(I27,CategoryTable,2,FALSE)),0) | G27: 0 | I27: Delivery & Logistics | J27: =IF(A28="","",A28) | K27: =IF(A28="","",ROUNDUP(F28/10,0)*10)
E28: =D28 | F28: =IFERROR(E28*(1+VLOOKUP(I28,CategoryTable,2,FALSE)),0) | G28: 0 | I28: Delivery & Logistics | J28: =IF(A29="","",A29) | K28: =IF(A29="","",ROUNDUP(F29/10,0)*10) | M28: TEAM NOTES
E29: =D29 | F29: =IFERROR(E29*(1+VLOOKUP(I29,CategoryTable,2,FALSE)),0) | G29: 0 | I29: Delivery & Logistics | J29: Floral Subtotal | K29: =SUM(K16:K28) | M29: Floral Vendor:
A30: FLORAL SUBTOTAL | E30: =SUM(E16:E25)+SUM(E27:E29) | F30: =SUM(F16:F25)+SUM(F27:F29)
J31: =A32 | M31: Rental Vendor(s):
A32: RENTALS & LOUNGE | J32: =IF(A35="","",A35&" x"&C35) | K32: =IF(A35="","",ROUNDUP(F35/10,0)*10)
A33: Item | B33: Vendor | C33: Qty | D33: Unit Price | E33: Our Cost | F33: Client Cost | G33: Tax Rate | H33: Notes / Description | J33: =IF(A36="","",A36&" x"&C36) | K33: =IF(A36="","",ROUNDUP(F36/10,0)*10) | M33: AV Vendor:
A34: SEATING (chairs, barstools, banquettes) | J34: =IF(A37="","",A37&" x"&C37) | K34: =IF(A37="","",ROUNDUP(F37/10,0)*10)
E35: =C35*D35 | F35: =IFERROR(E35*(1+VLOOKUP(I35,CategoryTable,2,FALSE)),0) | G35: ='Client Setup'!B19 | I35: Décor & Design | J35: =IF(A38="","",A38&" x"&C38) | K35: =IF(A38="","",ROUNDUP(F38/10,0)*10) | M35: Design Concept:
E36: =C36*D36 | F36: =IFERROR(E36*(1+VLOOKUP(I36,CategoryTable,2,FALSE)),0) | G36: ='Client Setup'!B19 | I36: Décor & Design | J36: =IF(A39="","",A39&" x"&C39) | K36: =IF(A39="","",ROUNDUP(F39/10,0)*10)
E37: =C37*D37 | F37: =IFERROR(E37*(1+VLOOKUP(I37,CategoryTable,2,FALSE)),0) | G37: ='Client Setup'!B19 | I37: Décor & Design | J37: =IF(A40="","",A40&" x"&C40) | K37: =IF(A40="","",ROUNDUP(F40/10,0)*10)
E38: =C38*D38 | F38: =IFERROR(E38*(1+VLOOKUP(I38,CategoryTable,2,FALSE)),0) | G38: ='Client Setup'!B19 | I38: Décor & Design | J38: =IF(A41="","",A41&" x"&C41) | K38: =IF(A41="","",ROUNDUP(F41/10,0)*10) | M38: Logistics:
E39: =C39*D39 | F39: =IFERROR(E39*(1+VLOOKUP(I39,CategoryTable,2,FALSE)),0) | G39: ='Client Setup'!B19 | I39: Décor & Design | J39: =IF(A42="","",A42&" x"&C42) | K39: =IF(A42="","",ROUNDUP(F42/10,0)*10)
E40: =C40*D40 | F40: =IFERROR(E40*(1+VLOOKUP(I40,CategoryTable,2,FALSE)),0) | G40: ='Client Setup'!B19 | I40: Décor & Design | J40: =IF(A44="","",A44&" x"&C44) | K40: =IF(A44="","",ROUNDUP(F44/10,0)*10) | M40: Additional Notes:
E41: =C41*D41 | F41: =IFERROR(E41*(1+VLOOKUP(I41,CategoryTable,2,FALSE)),0) | G41: ='Client Setup'!B19 | I41: Décor & Design | J41: =IF(A45="","",A45&" x"&C45) | K41: =IF(A45="","",ROUNDUP(F45/10,0)*10)
E42: =C42*D42 | F42: =IFERROR(E42*(1+VLOOKUP(I42,CategoryTable,2,FALSE)),0) | G42: ='Client Setup'!B19 | I42: Décor & Design | J42: =IF(A46="","",A46&" x"&C46) | K42: =IF(A46="","",ROUNDUP(F46/10,0)*10)
...

Sheet SAMPLE Decor Estimate
A2: Decor & Production Estimate
A4: EVENT INFO (from Client Setup) | J4: DETAILED CLIENT VIEW | M4: SUMMARY VIEW
A5: Client: | B5: ='Client Setup'!B5 | J5: Itemized — each section is one Canva slide | M5: Category totals for client
A6: Event Date: | B6: ='Client Setup'!B6
A7: Guest Count: | B7: ='Client Setup'!B7 | J7: DECOR & PRODUCTION ESTIMATE | M7: DECOR & PRODUCTION ESTIMATE
A8: Location: | B8: ='Client Setup'!B16 | J8: Color | K8: Meaning | M8: ='Client Setup'!B5 | N8: ='Client Setup'!B7&" Guests"
A9: Venue: | B9: 101 Constitution Ave NW, Washington DC | E9: Event Time: | F9: ='Client Setup'!B10 | J9: =TEXT('Client Setup'!B6,"MMMM D, YYYY") | K9: Dropdown — click to select | M9: =TEXT('Client Setup'!B6,"MMMM D, YYYY")
A10: Company: | B10: ='Client Setup'!B11 | K10: Manual entry or formula
A11: Program: | B11: ='Client Setup'!B12
A12: Client Hotel: | B12: ='Client Setup'!B13
A13: FLORALS
A14: Item | B14: Vendor | C14: Qty | D14: Unit Price | E14: Our Cost | F14: Client Cost | G14: Tax Rate | H14: Notes / Description | I14: Category | J14: Item | K14: Amount | M14: Category | N14: Amount
A15: TAXABLE FLORAL PRODUCT | J15: =A13 | M15: =A13 | N15: =ROUNDUP(F30/50,0)*50
A16: 4ft Table Florals | B16: Flowers at 38 | C16: 14 | D16: 90 | E16: =C16*D16 | F16: =IFERROR(E16*(1+VLOOKUP(I16,CategoryTable,2,FALSE)),0) | G16: ='Client Setup'!B19 | H16: Trio gold bud vases, cherry blossom, ranunculus, astilbe + 2 votives | I16: Décor & Design | J16: =IF(A16="","",A16&" x"&C16) | K16: =IF(A16="","",ROUNDUP(F16/10,0)*10) | M16: Seating | N16: =ROUNDUP(SUM(F35:F42)/50,0)*50
A17: Cocktail Table Florals | B17: Flowers at 38 | C17: 14 | D17: 31 | E17: =C17*D17 | F17: =IFERROR(E17*(1+VLOOKUP(I17,CategoryTable,2,FALSE)),0) | G17: ='Client Setup'!B19 | H17: Single bud vase + single ribbed votive | I17: Décor & Design | J17: =IF(A17="","",A17&" x"&C17) | K17: =IF(A17="","",ROUNDUP(F17/10,0)*10) | M17: Lounge Furniture | N17: =ROUNDUP(SUM(F44:F51)/50,0)*50
A18: Side Table Florals | B18: Flowers at 38 | C18: 2 | D18: 96 | E18: =C18*D18 | F18: =IFERROR(E18*(1+VLOOKUP(I18,CategoryTable,2,FALSE)),0) | G18: ='Client Setup'!B19 | H18: Trio gold bud vases, cherry blossom, ranunculus, astilbe + 4 votives | I18: Décor & Design | J18: =IF(A18="","",A18&" x"&C18) | K18: =IF(A18="","",ROUNDUP(F18/10,0)*10) | M18: Tables | N18: =ROUNDUP(SUM(F53:F60)/50,0)*50
E19: =C19*D19 | F19: =IFERROR(E19*(1+VLOOKUP(I19,CategoryTable,2,FALSE)),0) | G19: ='Client Setup'!B19 | I19: Décor & Design | J19: =IF(A19="","",A19&" x"&C19) | K19: =IF(A19="","",ROUNDUP(F19/10,0)*10) | M19: Decor & Accessories | N19: =ROUNDUP(SUM(F62:F67)/50,0)*50
E20: =C20*D20 | F20: =IFERROR(E20*(1+VLOOKUP(I20,CategoryTable,2,FALSE)),0) | G20: ='Client Setup'!B19 | I20: Décor & Design | J20: =IF(A20="","",A20&" x"&C20) | K20: =IF(A20="","",ROUNDUP(F20/10,0)*10) | M20: Delivery & Fees | N20: =ROUNDUP((SUM(F27:F29)+SUM(F69:F74)+SUM(F91:F95))/50,0)*50
E21: =C21*D21 | F21: =IFERROR(E21*(1+VLOOKUP(I21,CategoryTable,2,FALSE)),0) | G21: ='Client Setup'!B19 | I21: Décor & Design | J21: =IF(A21="","",A21&" x"&C21) | K21: =IF(A21="","",ROUNDUP(F21/10,0)*10) | M21: =A77 | N21: =ROUNDUP(SUM(F80:F89)/50,0)*50
E22: =C22*D22 | F22: =IFERROR(E22*(1+VLOOKUP(I22,CategoryTable,2,FALSE)),0) | G22: ='Client Setup'!B19 | I22: Décor & Design | J22: =IF(A22="","",A22&" x"&C22) | K22: =IF(A22="","",ROUNDUP(F22/10,0)*10) | M22: Tax | N22: =ROUNDUP(F100/50,0)*50
E23: =C23*D23 | F23: =IFERROR(E23*(1+VLOOKUP(I23,CategoryTable,2,FALSE)),0) | G23: ='Client Setup'!B19 | I23: Décor & Design | J23: =IF(A23="","",A23&" x"&C23) | K23: =IF(A23="","",ROUNDUP(F23/10,0)*10)
E24: =C24*D24 | F24: =IFERROR(E24*(1+VLOOKUP(I24,CategoryTable,2,FALSE)),0) | G24: ='Client Setup'!B19 | I24: Décor & Design | J24: =IF(A24="","",A24&" x"&C24) | K24: =IF(A24="","",ROUNDUP(F24/10,0)*10) | M24: TOTAL ESTIMATE | N24: =SUM(N15:N22)
E25: =C25*D25 | F25: =IFERROR(E25*(1+VLOOKUP(I25,CategoryTable,2,FALSE)),0) | G25: ='Client Setup'!B19 | I25: Décor & Design | J25: =IF(A25="","",A25&" x"&C25) | K25: =IF(A25="","",ROUNDUP(F25/10,0)*10) | M25: Guest Count | N25: ='Client Setup'!B7
A26: NON-TAXABLE FLORAL FEES | J26: =IF(A27="","",A27) | K26: =IF(A27="","",ROUNDUP(F27/10,0)*10)
A27: Delivery/Setup & Strike | B27: Flowers at 38 | D27: 188.6 | E27: =D27 | F27: =IFERROR(E27*(1+VLOOKUP(I27,CategoryTable,2,FALSE)),0) | G27: 0 | H27: Tax exempt on vendor invoice — resale on file | I27: Delivery & Logistics | J27: =IF(A28="","",A28) | K27: =IF(A28="","",ROUNDUP(F28/10,0)*10)
E28: =D28 | F28: =IFERROR(E28*(1+VLOOKUP(I28,CategoryTable,2,FALSE)),0) | G28: 0 | I28: Delivery & Logistics | J28: =IF(A29="","",A29) | K28: =IF(A29="","",ROUNDUP(F29/10,0)*10) | M28: TEAM NOTES
E29: =D29 | F29: =IFERROR(E29*(1+VLOOKUP(I29,CategoryTable,2,FALSE)),0) | G29: 0 | I29: Delivery & Logistics | J29: Floral Subtotal | K29: =SUM(K16:K28) | M29: Floral Vendor:
A30: FLORAL SUBTOTAL | E30: =SUM(E16:E25)+SUM(E27:E29) | F30: =SUM(F16:F25)+SUM(F27:F29)
J31: =A32 | M31: Rental Vendor(s):
A32: RENTALS & LOUNGE | J32: =IF(A35="","",A35&" x"&C35) | K32: =IF(A35="","",ROUNDUP(F35/10,0)*10)
A33: Item | B33: Vendor | C33: Qty | D33: Unit Price | E33: Our Cost | F33: Client Cost | G33: Tax Rate | H33: Notes / Description | J33: =IF(A36="","",A36&" x"&C36) | K33: =IF(A36="","",ROUNDUP(F36/10,0)*10) | M33: AV Vendor:
A34: SEATING (chairs, barstools, banquettes) | J34: =IF(A37="","",A37&" x"&C37) | K34: =IF(A37="","",ROUNDUP(F37/10,0)*10)
A35: Paris Oval Back Chair | B35: White Glove | C35: 84 | D35: 21 | E35: =C35*D35 | F35: =IFERROR(E35*(1+VLOOKUP(I35,CategoryTable,2,FALSE)),0) | G35: ='Client Setup'!B19 | I35: Décor & Design | J35: =IF(A38="","",A38&" x"&C38) | K35: =IF(A38="","",ROUNDUP(F38/10,0)*10) | M35: Design Concept:
A36: Ritz Mauve Circular Banquette | B36: White Glove | C36: 2 | D36: 395 | E36: =C36*D36 | F36: =IFERROR(E36*(1+VLOOKUP(I36,CategoryTable,2,FALSE)),0) | G36: ='Client Setup'!B19 | I36: Décor & Design | J36: =IF(A39="","",A39&" x"&C39) | K36: =IF(A39="","",ROUNDUP(F39/10,0)*10)
E37: =C37*D37 | F37: =IFERROR(E37*(1+VLOOKUP(I37,CategoryTable,2,FALSE)),0) | G37: ='Client Setup'!B19 | I37: Décor & Design | J37: =IF(A40="","",A40&" x"&C40) | K37: =IF(A40="","",ROUNDUP(F40/10,0)*10)
E38: =C38*D38 | F38: =IFERROR(E38*(1+VLOOKUP(I38,CategoryTable,2,FALSE)),0) | G38: ='Client Setup'!B19 | I38: Décor & Design | J38: =IF(A41="","",A41&" x"&C41) | K38: =IF(A41="","",ROUNDUP(F41/10,0)*10) | M38: Logistics:
E39: =C39*D39 | F39: =IFERROR(E39*(1+VLOOKUP(I39,CategoryTable,2,FALSE)),0) | G39: ='Client Setup'!B19 | I39: Décor & Design | J39: =IF(A42="","",A42&" x"&C42) | K39: =IF(A42="","",ROUNDUP(F42/10,0)*10)
E40: =C40*D40 | F40: =IFERROR(E40*(1+VLOOKUP(I40,CategoryTable,2,FALSE)),0) | G40: ='Client Setup'!B19 | I40: Décor & Design | J40: =IF(A44="","",A44&" x"&C44) | K40: =IF(A44="","",ROUNDUP(F44/10,0)*10) | M40: Additional Notes:
E41: =C41*D41 | F41: =IFERROR(E41*(1+VLOOKUP(I41,CategoryTable,2,FALSE)),0) | G41: ='Client Setup'!B19 | I41: Décor & Design | J41: =IF(A45="","",A45&" x"&C45) | K41: =IF(A45="","",ROUNDUP(F45/10,0)*10)
E42: =C42*D42 | F42: =IFERROR(E42*(1+VLOOKUP(I42,CategoryTable,2,FALSE)),0) | G42: ='Client Setup'!B19 | I42: Décor & Design | J42: =IF(A46="","",A46&" x"&C46) | K42: =IF(A46="","",ROUNDUP(F46/10,0)*10)
...
